<?xml version='1.0'?>
  <sdf version='1.7'>
    <model name='land_robot'>
        
        <pose>0 0 1 0 0.0 3.14</pose>

        <link name="base_footprint">
          <pose>-0.110726 -0.145588 -0.265574 0 -0 0</pose>
        </link>

        <link name='base_link'>

          <inertial>
            <mass>5</mass>
            <inertia>
              <ixx>0.166667</ixx>
              <ixy>0</ixy>
              <ixz>0</ixz>
              <iyy>0.166667</iyy>
              <iyz>0</iyz>
              <izz>0.166667</izz>
            </inertia>
            <pose>0 0 0 0 -0 0</pose>
          </inertial>

          <pose>-0.110726 -0.145588 -0.265574 0 -0 0</pose>
          <gravity>1</gravity>
          <self_collide>0</self_collide>
          <kinematic>0</kinematic>
          <enable_wind>0</enable_wind>
          
          <visual name='visual'>
            <pose>0 0 0 0 -0 0</pose>
            <geometry>
              <box>
                <size>1 0.75 0.2</size>
              </box>
            </geometry>
            <material>
              <lighting>1</lighting>
              <script>
                <uri>file://media/materials/scripts/gazebo.material</uri>
                <name>Gazebo/Grey</name>
              </script>
              <shader type='pixel'>
                <normal_map>__default__</normal_map>
              </shader>
              <ambient>0.1 0.1 0.1 1</ambient>
              <diffuse>0.1 0.1 0.1 1</diffuse>
              <specular>0.1 0.1 0.1 1</specular>
              <emissive>0 0 0 1</emissive>
            </material>
            <transparency>0</transparency>
            <cast_shadows>1</cast_shadows>
          </visual>

          <collision name='collision'>
            <laser_retro>0</laser_retro>
            <max_contacts>10</max_contacts>
            <pose>0 0 0 0 -0 0</pose>
            <geometry>
              <box>
                <size>1 0.75 0.2</size>
              </box>
            </geometry>
            <surface>
              <friction>
                <ode>
                  <mu>1</mu>
                  <mu2>1</mu2>
                  <fdir1>0 0 0</fdir1>
                  <slip1>0</slip1>
                  <slip2>0</slip2>
                </ode>
                <torsional>
                  <coefficient>1</coefficient>
                  <patch_radius>0</patch_radius>
                  <surface_radius>0</surface_radius>
                  <use_patch_radius>1</use_patch_radius>
                  <ode>
                    <slip>0</slip>
                  </ode>
                </torsional>
              </friction>
              <bounce>
                <restitution_coefficient>0</restitution_coefficient>
                <threshold>1e+06</threshold>
              </bounce>
              <contact>
                <collide_without_contact>0</collide_without_contact>
                <collide_without_contact_bitmask>1</collide_without_contact_bitmask>
                <collide_bitmask>1</collide_bitmask>
                <ode>
                  <soft_cfm>0</soft_cfm>
                  <soft_erp>0.2</soft_erp>
                  <kp>1e+13</kp>
                  <kd>1</kd>
                  <max_vel>0.01</max_vel>
                  <min_depth>0</min_depth>
                </ode>
                <bullet>
                  <split_impulse>1</split_impulse>
                  <split_impulse_penetration_threshold>-0.01</split_impulse_penetration_threshold>
                  <soft_cfm>0</soft_cfm>
                  <soft_erp>0.2</soft_erp>
                  <kp>1e+13</kp>
                  <kd>1</kd>
                </bullet>
              </contact>
            </surface>
          </collision>

        </link>

        <link name='rueda_der_tras'>
          <inertial>
            <mass>5</mass>
            <inertia>
              <ixx>0.145833</ixx>
              <ixy>0</ixy>
              <ixz>0</ixz>
              <iyy>0.145833</iyy>
              <iyz>0</iyz>
              <izz>0.125</izz>
            </inertia>
            <pose>0 0 0 0 -0 0</pose>
          </inertial>
          <pose>-0.437626 -0.571744 -0.298299 1.5708 -0 0</pose>
          <gravity>1</gravity>
          <self_collide>0</self_collide>
          <kinematic>0</kinematic>
          <enable_wind>0</enable_wind>
          <visual name='visual'>
            <pose>0 0 0 0 -0 0</pose>
            <geometry>
              <cylinder>
                <radius>0.2</radius>
                <length>0.1</length>
              </cylinder>
            </geometry>
            <material>
              <lighting>1</lighting>
              <script>
                <uri>file://media/materials/scripts/gazebo.material</uri>
                <name>Gazebo/Grey</name>
              </script>
              <shader type='pixel'>
                <normal_map>__default__</normal_map>
              </shader>
              <ambient>0.3 0.3 0.3 1</ambient>
              <diffuse>0.7 0.7 0.7 1</diffuse>
              <specular>0.01 0.01 0.01 1</specular>
              <emissive>0 0 0 1</emissive>
            </material>
            <transparency>0</transparency>
            <cast_shadows>1</cast_shadows>
          </visual>
          <collision name='collision'>
            <laser_retro>0</laser_retro>
            <max_contacts>10</max_contacts>
            <pose>0 0 0 0 -0 0</pose>
            <geometry>
              <cylinder>
                <radius>0.2</radius>
                <length>0.1</length>
              </cylinder>
            </geometry>
            <surface>
              <friction>
                <ode>
                  <mu>0.1</mu>
                  <mu2>0.1</mu2>
                  <fdir1>0 0 0</fdir1>
                  <slip1>0</slip1>
                  <slip2>0</slip2>
                </ode>
                <torsional>
                  <coefficient>1</coefficient>
                  <patch_radius>0</patch_radius>
                  <surface_radius>0</surface_radius>
                  <use_patch_radius>1</use_patch_radius>
                  <ode>
                    <slip>0</slip>
                  </ode>
                </torsional>
              </friction>
              <bounce>
                <restitution_coefficient>0</restitution_coefficient>
                <threshold>1e+06</threshold>
              </bounce>
              <contact>
                <collide_without_contact>0</collide_without_contact>
                <collide_without_contact_bitmask>1</collide_without_contact_bitmask>
                <collide_bitmask>1</collide_bitmask>
                <ode>
                  <soft_cfm>0</soft_cfm>
                  <soft_erp>0.2</soft_erp>
                  <kp>1e+13</kp>
                  <kd>1</kd>
                  <max_vel>0.01</max_vel>
                  <min_depth>0</min_depth>
                </ode>
                <bullet>
                  <split_impulse>1</split_impulse>
                  <split_impulse_penetration_threshold>-0.01</split_impulse_penetration_threshold>
                  <soft_cfm>0</soft_cfm>
                  <soft_erp>0.2</soft_erp>
                  <kp>1e+13</kp>
                  <kd>1</kd>
                </bullet>
              </contact>
            </surface>
          </collision>
        </link>

        <link name='rueda_der_del'>
          <inertial>
            <mass>5</mass>
            <inertia>
              <ixx>0.145833</ixx>
              <ixy>0</ixy>
              <ixz>0</ixz>
              <iyy>0.145833</iyy>
              <iyz>0</iyz>
              <izz>0.125</izz>
            </inertia>
            <pose>0 0 0 0 -0 0</pose>
          </inertial>
          <pose>0.171311 -0.571744 -0.298299 1.5708 -0 0</pose>
          <gravity>1</gravity>
          <self_collide>0</self_collide>
          <kinematic>0</kinematic>
          <enable_wind>0</enable_wind>
          <visual name='visual'>
            <pose>0 0 0 0 -0 0</pose>
            <geometry>
              <cylinder>
                <radius>0.2</radius>
                <length>0.1</length>
              </cylinder>
            </geometry>
            <material>
              <lighting>1</lighting>
              <script>
                <uri>file://media/materials/scripts/gazebo.material</uri>
                <name>Gazebo/Grey</name>
              </script>
              <shader type='pixel'>
                <normal_map>__default__</normal_map>
              </shader>
              <ambient>0.3 0.3 0.3 1</ambient>
              <diffuse>0.7 0.7 0.7 1</diffuse>
              <specular>0.01 0.01 0.01 1</specular>
              <emissive>0 0 0 1</emissive>
            </material>
            <transparency>0</transparency>
            <cast_shadows>1</cast_shadows>
          </visual>
          <collision name='collision'>
            <laser_retro>0</laser_retro>
            <max_contacts>10</max_contacts>
            <pose>0 0 0 0 -0 0</pose>
            <geometry>
              <cylinder>
                <radius>0.2</radius>
                <length>0.1</length>
              </cylinder>
            </geometry>
            <surface>
              <friction>
                <ode>
                  <mu>1</mu>
                  <mu2>1</mu2>
                  <fdir1>0 0 0</fdir1>
                  <slip1>0</slip1>
                  <slip2>0</slip2>
                </ode>
                <torsional>
                  <coefficient>1</coefficient>
                  <patch_radius>0</patch_radius>
                  <surface_radius>0</surface_radius>
                  <use_patch_radius>1</use_patch_radius>
                  <ode>
                    <slip>0</slip>
                  </ode>
                </torsional>
              </friction>
              <bounce>
                <restitution_coefficient>0</restitution_coefficient>
                <threshold>1e+06</threshold>
              </bounce>
              <contact>
                <collide_without_contact>0</collide_without_contact>
                <collide_without_contact_bitmask>1</collide_without_contact_bitmask>
                <collide_bitmask>1</collide_bitmask>
                <ode>
                  <soft_cfm>0</soft_cfm>
                  <soft_erp>0.2</soft_erp>
                  <kp>1e+13</kp>
                  <kd>1</kd>
                  <max_vel>0.01</max_vel>
                  <min_depth>0</min_depth>
                </ode>
                <bullet>
                  <split_impulse>1</split_impulse>
                  <split_impulse_penetration_threshold>-0.01</split_impulse_penetration_threshold>
                  <soft_cfm>0</soft_cfm>
                  <soft_erp>0.2</soft_erp>
                  <kp>1e+13</kp>
                  <kd>1</kd>
                </bullet>
              </contact>
            </surface>
          </collision>
        </link>

        <link name='rueda_izq_tras'>
          <inertial>
            <mass>5</mass>
            <inertia>
              <ixx>0.145833</ixx>
              <ixy>0</ixy>
              <ixz>0</ixz>
              <iyy>0.145833</iyy>
              <iyz>0</iyz>
              <izz>0.125</izz>
            </inertia>
            <pose>0 0 0 0 -0 0</pose>
          </inertial>
          <pose>-0.437626 0.280995 -0.298299 1.5708 -0 0</pose>
          <gravity>1</gravity>
          <self_collide>0</self_collide>
          <kinematic>0</kinematic>
          <enable_wind>0</enable_wind>
          <visual name='visual'>
            <pose>0 0 0 0 -0 0</pose>
            <geometry>
              <cylinder>
                <radius>0.2</radius>
                <length>0.1</length>
              </cylinder>
            </geometry>
            <material>
              <lighting>1</lighting>
              <script>
                <uri>file://media/materials/scripts/gazebo.material</uri>
                <name>Gazebo/Grey</name>
              </script>
              <shader type='pixel'>
                <normal_map>__default__</normal_map>
              </shader>
              <ambient>0.3 0.3 0.3 1</ambient>
              <diffuse>0.7 0.7 0.7 1</diffuse>
              <specular>0.01 0.01 0.01 1</specular>
              <emissive>0 0 0 1</emissive>
            </material>
            <transparency>0</transparency>
            <cast_shadows>1</cast_shadows>
          </visual>
          <collision name='collision'>
            <laser_retro>0</laser_retro>
            <max_contacts>10</max_contacts>
            <pose>0 0 0 0 -0 0</pose>
            <geometry>
              <cylinder>
                <radius>0.2</radius>
                <length>0.1</length>
              </cylinder>
            </geometry>
            <surface>
              <friction>
                <ode>
                  <mu>0.1</mu>
                  <mu2>0.1</mu2>
                  <fdir1>0 0 0</fdir1>
                  <slip1>0</slip1>
                  <slip2>0</slip2>
                </ode>
                <torsional>
                  <coefficient>1</coefficient>
                  <patch_radius>0</patch_radius>
                  <surface_radius>0</surface_radius>
                  <use_patch_radius>1</use_patch_radius>
                  <ode>
                    <slip>0</slip>
                  </ode>
                </torsional>
              </friction>
              <bounce>
                <restitution_coefficient>0</restitution_coefficient>
                <threshold>1e+06</threshold>
              </bounce>
              <contact>
                <collide_without_contact>0</collide_without_contact>
                <collide_without_contact_bitmask>1</collide_without_contact_bitmask>
                <collide_bitmask>1</collide_bitmask>
                <ode>
                  <soft_cfm>0</soft_cfm>
                  <soft_erp>0.2</soft_erp>
                  <kp>1e+13</kp>
                  <kd>1</kd>
                  <max_vel>0.01</max_vel>
                  <min_depth>0</min_depth>
                </ode>
                <bullet>
                  <split_impulse>1</split_impulse>
                  <split_impulse_penetration_threshold>-0.01</split_impulse_penetration_threshold>
                  <soft_cfm>0</soft_cfm>
                  <soft_erp>0.2</soft_erp>
                  <kp>1e+13</kp>
                  <kd>1</kd>
                </bullet>
              </contact>
            </surface>
          </collision>
        </link>

        <link name='rueda_izq_del'>
          <inertial>
            <mass>5</mass>
            <inertia>
              <ixx>0.145833</ixx>
              <ixy>0</ixy>
              <ixz>0</ixz>
              <iyy>0.145833</iyy>
              <iyz>0</iyz>
              <izz>0.125</izz>
            </inertia>
            <pose>0 0 0 0 -0 0</pose>
          </inertial>
          <pose>0.171311 0.280995 -0.298299 1.5708 -0 0</pose>
          <gravity>1</gravity>
          <self_collide>0</self_collide>
          <kinematic>0</kinematic>
          <enable_wind>0</enable_wind>
          <visual name='visual'>
            <pose>0 0 0 0 -0 0</pose>
            <geometry>
              <cylinder>
                <radius>0.2</radius>
                <length>0.1</length>
              </cylinder>
            </geometry>
            <material>
              <lighting>1</lighting>
              <script>
                <uri>file://media/materials/scripts/gazebo.material</uri>
                <name>Gazebo/Grey</name>
              </script>
              <shader type='pixel'>
                <normal_map>__default__</normal_map>
              </shader>
              <ambient>0.3 0.3 0.3 1</ambient>
              <diffuse>0.7 0.7 0.7 1</diffuse>
              <specular>0.01 0.01 0.01 1</specular>
              <emissive>0 0 0 1</emissive>
            </material>
            <transparency>0</transparency>
            <cast_shadows>1</cast_shadows>
          </visual>
          <collision name='collision'>
            <laser_retro>0</laser_retro>
            <max_contacts>10</max_contacts>
            <pose>0 0 0 0 -0 0</pose>
            <geometry>
              <cylinder>
                <radius>0.2</radius>
                <length>0.1</length>
              </cylinder>
            </geometry>
            <surface>
              <friction>
                <ode>
                  <mu>1</mu>
                  <mu2>1</mu2>
                  <fdir1>0 0 0</fdir1>
                  <slip1>0</slip1>
                  <slip2>0</slip2>
                </ode>
                <torsional>
                  <coefficient>1</coefficient>
                  <patch_radius>0</patch_radius>
                  <surface_radius>0</surface_radius>
                  <use_patch_radius>1</use_patch_radius>
                  <ode>
                    <slip>0</slip>
                  </ode>
                </torsional>
              </friction>
              <bounce>
                <restitution_coefficient>0</restitution_coefficient>
                <threshold>1e+06</threshold>
              </bounce>
              <contact>
                <collide_without_contact>0</collide_without_contact>
                <collide_without_contact_bitmask>1</collide_without_contact_bitmask>
                <collide_bitmask>1</collide_bitmask>
                <ode>
                  <soft_cfm>0</soft_cfm>
                  <soft_erp>0.2</soft_erp>
                  <kp>1e+13</kp>
                  <kd>1</kd>
                  <max_vel>0.01</max_vel>
                  <min_depth>0</min_depth>
                </ode>
                <bullet>
                  <split_impulse>1</split_impulse>
                  <split_impulse_penetration_threshold>-0.01</split_impulse_penetration_threshold>
                  <soft_cfm>0</soft_cfm>
                  <soft_erp>0.2</soft_erp>
                  <kp>1e+13</kp>
                  <kd>1</kd>
                </bullet>
              </contact>
            </surface>
          </collision>
        </link>

        <link name='soporte_camara'>
          <inertial>
            <mass>1</mass>
            <inertia>
              <ixx>0.145833</ixx>
              <ixy>0</ixy>
              <ixz>0</ixz>
              <iyy>0.145833</iyy>
              <iyz>0</iyz>
              <izz>0.125</izz>
            </inertia>
            <pose>0 0 0 0 -0 0</pose>
          </inertial>
          <pose>0.250663 -0.155261 0.031715 0 -0 0</pose>
          <gravity>1</gravity>
          <self_collide>0</self_collide>
          <kinematic>0</kinematic>
          <enable_wind>0</enable_wind>
          <visual name='visual'>
            <pose>0 0 0 0 -0 0</pose>
            <geometry>
              <cylinder>
                <radius>0.025</radius>
                <length>0.4</length>
              </cylinder>
            </geometry>
            <material>
              <lighting>1</lighting>
              <script>
                <uri>file://media/materials/scripts/gazebo.material</uri>
                <name>Gazebo/Grey</name>
              </script>
              <shader type='pixel'>
                <normal_map>__default__</normal_map>
              </shader>
              <ambient>0.3 0.3 0.3 1</ambient>
              <diffuse>0.7 0.7 0.7 1</diffuse>
              <specular>0.01 0.01 0.01 1</specular>
              <emissive>0 0 0 1</emissive>
            </material>
            <transparency>0</transparency>
            <cast_shadows>1</cast_shadows>
          </visual>
          <collision name='collision'>
            <laser_retro>0</laser_retro>
            <max_contacts>10</max_contacts>
            <pose>0 0 0 0 -0 0</pose>
            <geometry>
              <cylinder>
                <radius>0.025</radius>
                <length>0.4</length>
              </cylinder>
            </geometry>
            <surface>
              <friction>
                <ode>
                  <mu>0.1</mu>
                  <mu2>0.1</mu2>
                  <fdir1>0 0 0</fdir1>
                  <slip1>0</slip1>
                  <slip2>0</slip2>
                </ode>
                <torsional>
                  <coefficient>1</coefficient>
                  <patch_radius>0</patch_radius>
                  <surface_radius>0</surface_radius>
                  <use_patch_radius>1</use_patch_radius>
                  <ode>
                    <slip>0</slip>
                  </ode>
                </torsional>
              </friction>
              <bounce>
                <restitution_coefficient>0</restitution_coefficient>
                <threshold>1e+06</threshold>
              </bounce>
              <contact>
                <collide_without_contact>0</collide_without_contact>
                <collide_without_contact_bitmask>1</collide_without_contact_bitmask>
                <collide_bitmask>1</collide_bitmask>
                <ode>
                  <soft_cfm>0</soft_cfm>
                  <soft_erp>0.2</soft_erp>
                  <kp>1e+13</kp>
                  <kd>1</kd>
                  <max_vel>0.01</max_vel>
                  <min_depth>0</min_depth>
                </ode>
                <bullet>
                  <split_impulse>1</split_impulse>
                  <split_impulse_penetration_threshold>-0.01</split_impulse_penetration_threshold>
                  <soft_cfm>0</soft_cfm>
                  <soft_erp>0.2</soft_erp>
                  <kp>1e+13</kp>
                  <kd>1</kd>
                </bullet>
              </contact>
            </surface>
          </collision>
        </link>

        <link name='camara'>
          <inertial>
              <mass>1</mass>
              <inertia>
                <ixx>0.166667</ixx>
                <ixy>0</ixy>
                <ixz>0</ixz>
                <iyy>0.166667</iyy>
                <iyz>0</iyz>
                <izz>0.166667</izz>
              </inertia>
              <pose>0 0 0 0 -0 0</pose>
          </inertial>
          <pose>0.250663 -0.155261 0.22 0 -0 0</pose>
          <gravity>1</gravity>
          <self_collide>0</self_collide>
          <kinematic>0</kinematic>
          <enable_wind>0</enable_wind>
          <visual name='visual'>
            <pose>0 0 0 0 -0 0</pose>
            <geometry>
              <box>
                <size>0.050000 0.100000 0.05000</size>
              </box>
            </geometry>
            <material>
              <lighting>1</lighting>
              <script>
                <uri>file://media/materials/scripts/gazebo.material</uri>
                <name>Gazebo/Grey</name>
              </script>
              <shader type='pixel'>
                <normal_map>__default__</normal_map>
              </shader>
              <ambient>0.1 0.1 0.1 1</ambient>
              <diffuse>0.1 0.1 0.1 1</diffuse>
              <specular>0.1 0.1 0.1 1</specular>
              <emissive>0 0 0 1</emissive>
            </material>
            <transparency>0</transparency>
            <cast_shadows>1</cast_shadows>
          </visual>
          <collision name='collision'>
            <laser_retro>0</laser_retro>
            <max_contacts>10</max_contacts>
            <pose>0 0 0 0 -0 0</pose>
            <geometry>
              <box>
                <size>0.050000 0.100000 0.050000</size>
              </box>
            </geometry>
            <surface>
              <friction>
                <ode>
                  <mu>1</mu>
                  <mu2>1</mu2>
                  <fdir1>0 0 0</fdir1>
                  <slip1>0</slip1>
                  <slip2>0</slip2>
                </ode>
                <torsional>
                  <coefficient>1</coefficient>
                  <patch_radius>0</patch_radius>
                  <surface_radius>0</surface_radius>
                  <use_patch_radius>1</use_patch_radius>
                  <ode>
                    <slip>0</slip>
                  </ode>
                </torsional>
              </friction>
              <bounce>
                <restitution_coefficient>0</restitution_coefficient>
                <threshold>1e+06</threshold>
              </bounce>
              <contact>
                <collide_without_contact>0</collide_without_contact>
                <collide_without_contact_bitmask>1</collide_without_contact_bitmask>
                <collide_bitmask>1</collide_bitmask>
                <ode>
                  <soft_cfm>0</soft_cfm>
                  <soft_erp>0.2</soft_erp>
                  <kp>1e+13</kp>
                  <kd>1</kd>
                  <max_vel>0.01</max_vel>
                  <min_depth>0</min_depth>
                </ode>
                <bullet>
                  <split_impulse>1</split_impulse>
                  <split_impulse_penetration_threshold>-0.01</split_impulse_penetration_threshold>
                  <soft_cfm>0</soft_cfm>
                  <soft_erp>0.2</soft_erp>
                  <kp>1e+13</kp>
                  <kd>1</kd>
                </bullet>
              </contact>
            </surface>
          </collision>
          <sensor name="camera" type="camera">
            <camera>
                <horizontal_fov>1.047</horizontal_fov>
                <image>
                    <width>640</width>
                    <height>840</height>
                </image>
                <clip>
                    <near>0.1</near>
                    <far>100</far>
                </clip>
            </camera>

            <always_on>1</always_on>
            <update_rate>30</update_rate>
            <visualize>true</visualize>
            <topic>camera</topic>

          </sensor>
        </link>

        <link name='lidar'>
          <inertial>
              <mass>1</mass>
              <inertia>
                <ixx>0</ixx>
                <ixy>0</ixy>
                <ixz>0</ixz>
                <iyy>0</iyy>
                <iyz>0</iyz>
                <izz>0</izz>
              </inertia>
              <pose>0 0 0 0 0 0</pose>
          </inertial>
          <!--pose>0.3 -0.4 -0.125 1.5708 -0 0</pose-->
          <pose>0.3 -0.4 -0.125 0 -0 0</pose>
          <gravity>1</gravity>
          <self_collide>0</self_collide>
          <kinematic>0</kinematic>
          <enable_wind>0</enable_wind>
          <visual name='visual'>
            <pose>0 0 0 -1.57 0 0</pose>
            <geometry>
              <cylinder>
                <radius>0.09</radius>
                <length>0.1</length>
              </cylinder>
            </geometry>
            <material>
              <lighting>1</lighting>
              <script>
                <uri>file://media/materials/scripts/gazebo.material</uri>
                <name>Gazebo/Grey</name>
              </script>
              <shader type='pixel'>
                <normal_map>__default__</normal_map>
              </shader>
              <ambient>0.1 0.1 0.1 1</ambient>
              <diffuse>0.1 0.1 0.1 1</diffuse>
              <specular>0.1 0.1 0.1 1</specular>
              <emissive>0 0 0 1</emissive>
            </material>
            <transparency>0</transparency>
            <cast_shadows>1</cast_shadows>
          </visual>
          <collision name='collision'>
            <laser_retro>0</laser_retro>
            <max_contacts>10</max_contacts>
            <pose>0 0 0 0 -0 0</pose>
            <geometry>
              <cylinder>
                <radius>0.2</radius>
                <length>0.1</length>
              </cylinder>
            </geometry>
            <surface>
              <friction>
                <ode>
                  <mu>0.1</mu>
                  <mu2>0.1</mu2>
                  <fdir1>0 0 0</fdir1>
                  <slip1>0</slip1>
                  <slip2>0</slip2>
                </ode>
                <torsional>
                  <coefficient>1</coefficient>
                  <patch_radius>0</patch_radius>
                  <surface_radius>0</surface_radius>
                  <use_patch_radius>1</use_patch_radius>
                  <ode>
                    <slip>0</slip>
                  </ode>
                </torsional>
              </friction>
              <bounce>
                <restitution_coefficient>0</restitution_coefficient>
                <threshold>1e+06</threshold>
              </bounce>
              <contact>
                <collide_without_contact>0</collide_without_contact>
                <collide_without_contact_bitmask>1</collide_without_contact_bitmask>
                <collide_bitmask>1</collide_bitmask>
                <ode>
                  <soft_cfm>0</soft_cfm>
                  <soft_erp>0.2</soft_erp>
                  <kp>1e+13</kp>
                  <kd>1</kd>
                  <max_vel>0.01</max_vel>
                  <min_depth>0</min_depth>
                </ode>
                <bullet>
                  <split_impulse>1</split_impulse>
                  <split_impulse_penetration_threshold>-0.01</split_impulse_penetration_threshold>
                  <soft_cfm>0</soft_cfm>
                  <soft_erp>0.2</soft_erp>
                  <kp>1e+13</kp>
                  <kd>1</kd>
                </bullet>
              </contact>
            </surface>
          </collision>
          <sensor name='gpu_lidar' type='gpu_lidar'>
            <pose>0 0 0 0 -0 0</pose>
              <topic>lidar</topic>
              <update_rate>20</update_rate>
              <lidar>
                <scan>
                  <horizontal>
                    <samples>640</samples>
                    <resolution>1</resolution>
                    <min_angle>-1.396263</min_angle>
                    <max_angle>1.396263</max_angle>
                  </horizontal>
                  <vertical>
                    <samples>1</samples>
                    <resolution>1</resolution>
                    <min_angle>0.0</min_angle>
                    <max_angle>0.0</max_angle>
                  </vertical>
                </scan>
                <range>
                  <min>0.08</min>
                  <max>10.0</max>
                  <resolution>0.01</resolution>
                </range>
              </lidar>
              <alwaysOn>1</alwaysOn>
              <visualize>true</visualize>
            </sensor>
        </link>

        <joint name="base_joint" type="fixed">
          <pose>0 0 0 0 -0 0</pose>
          <parent>base_footprint</parent>
          <child>base_link</child>
          <pose>0 0 0 0 -0 0</pose>
        </joint>

        <joint name='base_link_JOINT_rueda_der_tras' type='revolute'>
          <parent>base_link</parent>
          <child>rueda_der_tras</child>
          <pose>0 0 0 0 -0 0</pose>
          <axis>
            <xyz>0 0 -1</xyz>
            <limit>
              <lower>-1.79769e+308</lower>
              <upper>1.79769e+308</upper>
              <effort>-1</effort>
              <velocity>-1</velocity>
            </limit>
            <dynamics>
              <spring_reference>0</spring_reference>
              <spring_stiffness>0</spring_stiffness>
              <damping>0</damping>
              <friction>0</friction>
            </dynamics>
          </axis>
          <physics>
            <ode>
              <limit>
                <cfm>0</cfm>
                <erp>0.2</erp>
              </limit>
              <suspension>
                <cfm>0</cfm>
                <erp>0.2</erp>
              </suspension>
            </ode>
          </physics>
        </joint>

        <joint name='base_link_JOINT_rueda_der_del' type='revolute'>
          <parent>base_link</parent>
          <child>rueda_der_del</child>
          <pose>0 0 0 0 -0 0</pose>
          <axis>
            <xyz>0 0 -1</xyz>
            <limit>
              <lower>-1.79769e+308</lower>
              <upper>1.79769e+308</upper>
              <effort>-1</effort>
              <velocity>-1</velocity>
            </limit>
            <dynamics>
              <spring_reference>0</spring_reference>
              <spring_stiffness>0</spring_stiffness>
              <damping>0</damping>
            </dynamics>
          </axis>
          <physics>
            <ode>
              <limit>
                <cfm>0</cfm>
                <erp>0.2</erp>
              </limit>
              <suspension>
                <cfm>0</cfm>
                <erp>0.2</erp>
              </suspension>
            </ode>
          </physics>
        </joint>

        <joint name='base_link_JOINT_rueda_izq_tras' type='revolute'>
          <parent>base_link</parent>
          <child>rueda_izq_tras</child>
          <pose>0 0 0 0 -0 0</pose>
          <axis>
            <xyz>-0 -0 -1</xyz>
            <limit>
              <lower>-1.79769e+308</lower>
              <upper>1.79769e+308</upper>
              <effort>-1</effort>
              <velocity>-1</velocity>
            </limit>
            <dynamics>
              <spring_reference>0</spring_reference>
              <spring_stiffness>0</spring_stiffness>
              <damping>0</damping>
            </dynamics>
          </axis>
          <physics>
            <ode>
              <limit>
                <cfm>0</cfm>
                <erp>0.2</erp>
              </limit>
              <suspension>
                <cfm>0</cfm>
                <erp>0.2</erp>
              </suspension>
            </ode>
          </physics>
        </joint>

        <joint name='base_link_JOINT_rueda_izq_del' type='revolute'>
          <parent>base_link</parent>
          <child>rueda_izq_del</child>
          <pose>0 0 0 0 -0 0</pose>
          <axis>
            <xyz>-0 -0 -1</xyz>
            <limit>
              <lower>-1.79769e+308</lower>
              <upper>1.79769e+308</upper>
              <effort>-1</effort>
              <velocity>-1</velocity>
            </limit>
            <dynamics>
              <spring_reference>0</spring_reference>
              <spring_stiffness>0</spring_stiffness>
              <damping>0</damping>
            </dynamics>
          </axis>
          <physics>
            <ode>
              <limit>
                <cfm>0</cfm>
                <erp>0.2</erp>
              </limit>
              <suspension>
                <cfm>0</cfm>
                <erp>0.2</erp>
              </suspension>
            </ode>
          </physics>
        </joint>

        <joint name='base_link_JOINT_soporte_camara' type='revolute'>
          <parent>base_link</parent>
          <child>soporte_camara</child>
          <pose>0 0 0 0 -0 0</pose>
          <axis>
            <xyz>-0 -0 -1</xyz>
            <limit>
              <lower>-1.79769e+308</lower>
              <upper>1.79769e+308</upper>
              <effort>-1</effort>
              <velocity>-1</velocity>
            </limit>
            <dynamics>
              <spring_reference>0</spring_reference>
              <spring_stiffness>0</spring_stiffness>
              <damping>0</damping>
            </dynamics>
          </axis>
          <physics>
            <ode>
              <limit>
                <cfm>0</cfm>
                <erp>0.2</erp>
              </limit>
              <suspension>
                <cfm>0</cfm>
                <erp>0.2</erp>
              </suspension>
            </ode>
          </physics>
        </joint>

        <joint name='base_link_JOINT_camara' type='fixed'>
          <parent>soporte_camara</parent>
          <child>camara</child>
          <pose>0 0 0 0 -0 0</pose>
          <axis>
            <xyz>-0 -0 -1</xyz>
            <limit>
              <lower>-1.79769e+308</lower>
              <upper>1.79769e+308</upper>
              <effort>-1</effort>
              <velocity>-1</velocity>
            </limit>
            <dynamics>
              <spring_reference>0</spring_reference>
              <spring_stiffness>0</spring_stiffness>
              <damping>0</damping>
            </dynamics>
          </axis>
          <physics>
            <ode>
              <limit>
                <cfm>0</cfm>
                <erp>0.2</erp>
              </limit>
              <suspension>
                <cfm>0</cfm>
                <erp>0.2</erp>
              </suspension>
            </ode>
          </physics>
        </joint>

        <joint name='base_link_JOINT_lidar' type='fixed'>
          <parent>base_link</parent>
          <child>lidar</child>
          <pose>0 0 0 0 -0 0</pose>
          <axis>
            <xyz>-0 -0 -1</xyz>
            <limit>
              <lower>-1.79769e+308</lower>
              <upper>1.79769e+308</upper>
              <effort>-1</effort>
              <velocity>-1</velocity>
            </limit>
            <dynamics>
              <spring_reference>0</spring_reference>
              <spring_stiffness>0</spring_stiffness>
              <damping>0</damping>
            </dynamics>
          </axis>
          <physics>
            <ode>
              <limit>
                <cfm>0</cfm>
                <erp>0.2</erp>
              </limit>
              <suspension>
                <cfm>0</cfm>
                <erp>0.2</erp>
              </suspension>
            </ode>
          </physics>
        </joint>

        <static>0</static>
        <allow_auto_disable>1</allow_auto_disable>

        <plugin
            filename="ignition-gazebo-diff-drive-system"
            name="ignition::gazebo::systems::DiffDrive">
            <left_joint>base_link_JOINT_rueda_izq_del</left_joint>
            <right_joint>base_link_JOINT_rueda_der_del</right_joint>
            <wheel_separation>0.75</wheel_separation>
            <wheel_radius>0.25</wheel_radius>

            <odom_publish_frequency>20</odom_publish_frequency>
            <max_linear_acceleration>1</max_linear_acceleration>
            <min_linear_acceleration>-1</min_linear_acceleration>
            <max_angular_acceleration>2</max_angular_acceleration>
            <min_angular_acceleration>-2</min_angular_acceleration>
            <max_linear_velocity>0.5</max_linear_velocity>
            <min_linear_velocity>-0.5</min_linear_velocity>
            <max_angular_velocity>1</max_angular_velocity>
            <min_angular_velocity>-1</min_angular_velocity>
            <topic>/cmd_vel</topic>
            <base_frame_id>base_link</base_frame_id>
            <odom_frame_id>odom</odom_frame_id>
        </plugin>

        <plugin
            filename="ignition-gazebo-joint-position-controller-system"
            name="ignition::gazebo::systems::JointPositionController">
            <joint_name>base_link_JOINT_soporte_camara</joint_name>
            <topic>cmd_camera</topic>
            <p_gain>3.5</p_gain>
            <i_gain>0.01</i_gain>
            <d_gain>2</d_gain>
            <i_max>1</i_max>
            <i_min>-1</i_min>
            <cmd_max>1000</cmd_max>
            <cmd_min>-1000</cmd_min>
        </plugin>

        <plugin
            filename="libignition-gazebo-joint-state-publisher-system.so"
            name="ignition::gazebo::systems::JointStatePublisher">
            <joint_name>base_link_JOINT_rueda_izq_del</joint_name>
            <joint_name>base_link_JOINT_rueda_der_del</joint_name>
            <joint_name>base_link_JOINT_rueda_izq_tras</joint_name>
            <joint_name>base_link_JOINT_rueda_der_tras</joint_name>
            <joint_name>base_link_JOINT_soporte_camara</joint_name>
            
        </plugin>

    </model>
    
  </sdf>
